Workbook

Sheet basebid
A1: Project | D1: Project# | F1: DATE: | G1: Prepared BY | N1: 10 | O1: 1/2" | P1: 83 | Q1: ﻿#12 Thhn Stranded | T1: 108 | U1: #1 Thhn Stranded
A2: Elevator/Lobby/Corridors & Vacant Suite 3450 | D2: KM05 | F2: Todays Date | G2: KM | N2: 11 | O2: 3/4" | P2: 84 | Q2: #10 Thhn Stranded | T2: 109 | U2: #1/0 Thhn Stranded
A3: 120 N LaSalle | N3: 12 | O3: 1" | P3: 85 | Q3: #8 Thhn Stranded | T3: 110 | U3: #2/0 Thhn Stranded
A4: G.C. | N4: 13 | O4: 1-1/4" | P4: 86 | Q4: #6 Thhn Stranded | T4: 111 | U4: #3/0 Thhn Stranded
A5: Contact Name | N5: 14 | O5: 1-1/2" | P5: 87 | Q5: #4 Thhn Stranded | T5: 112 | U5: #4/0 Thhn Stranded
A6: Telephone - Fax | N6: 15 | O6: 2" | P6: 88 | Q6: #3 Thhn Stranded | T6: 113 | U6: #250 MCM Thhn Wire
N7: 16 | O7: 2-1/2" | P7: 89 | Q7: #2 Thhn Stranded | T7: 114 | U7: #300 MCM Thhn Wire
A8: MATERIAL | C8: QTY | D8: MAT UNIT | E8: per | F8: EXTENSION | G8: LBR UNIT | H8: per | I8: EXTENSION | J8: TOTAL | K8: $$/QTY | N8: 17 | O8: 3" | P8: 90 | Q8: #1 Thhn Stranded | T8: 115 | U8: #350 MCM Thhn Wire
N9: 18 | O9: 3-1/2" | P9: 91 | Q9: #1/0 Thhn Stranded | T9: 116 | U9: #400 MCM Thhn Wire
N10: 19 | O10: 4" | P10: 92 | Q10: #2/0 Thhn Stranded | T10: 117 | U10: #500 MCM Thhn Wire
A11: TEMP POWER | B11: =SUM(J12:J14) -> 0 | P11: 93 | Q11: #3/0 Thhn Stranded | T11: 118 | U11: #600 MCM Thhn Wire
A12: Temp power from ComEd permanent power | D12: =F326/100 -> 8285.2 | E12: Lot | F12: =+D12*C12 -> 0 | G12: =F326/10000 -> 82.852 | H12: Lot | I12: =+G12*C12 -> 0 | J12: =+(((I12*$I$323)+(F12*(1+$E$323)))*(1+$C$329)) -> 0 | K12: =IF(J12=0,0,J12/C12) -> 0 | P12: 94 | Q12: #4/0 Thhn Stranded | T12: 119 | U12: #750 MCM Thhn Wire
A13: Hook up of construction trailer | D13: 1500 | E13: Lot | F13: =+D13*C13 -> 0 | G13: 30 | H13: Lot | I13: =+G13*C13 -> 0 | J13: =+(((I13*$I$323)+(F13*(1+$E$323)))*(1+$C$329)) -> 0 | K13: =IF(J13=0,0,J13/C13) -> 0 | P13: 95 | Q13: #250 MCM Thhn Wire | T13: 120 | U13: #900 MCM Thhn Wire
P14: 96 | Q14: #300 MCM Thhn Wire
A15: ELECTRICAL SERVICE & DISTRIBUTION | B15: =SUM(J16:J158) -> 0 | K15: =IF(J15=0,0,J15/C15) -> 0 | P15: 97 | Q15: #350 MCM Thhn Wire
A16: ComEd pad | D16: 2000 | E16: E | F16: =+D16*C16 -> 0 | G16: 10 | H16: E | I16: =+G16*C16 -> 0 | J16: =+(((I16*$I$323)+(F16*(1+$E$323)))*(1+$C$329)) -> 0 | K16: =IF(J16=0,0,J16/C16) -> 0 | P16: 98 | Q16: #400 MCM Thhn Wire
A17: Rework existing panel for new loads | D17: 400 | E17: E | F17: =+D17*C17 -> 0 | G17: 4 | H17: E | I17: =+G17*C17 -> 0 | J17: =+(((I17*$I$323)+(F17*(1+$E$323)))*(1+$C$329)) -> 0 | K17: =IF(J17=0,0,J17/C17) -> 0 | P17: 99 | Q17: #500 MCM Thhn Wire
A18: 4000A., 277/480V., 3PH. Main switchboard w/ meter | D18: 35000 | E18: E | F18: =+D18*C18 -> 0 | G18: 124 | H18: E | I18: =+G18*C18 -> 0 | J18: =+(((I18*$I$323)+(F18*(1+$E$323)))*(1+$C$329)) -> 0 | K18: =IF(J18=0,0,J18/C18) -> 0 | P18: 100 | Q18: #600 MCM Thhn Wire
B19: CU feed (ft) | D19: =((FEEDERS!$D$100*4)/10+FEEDERS!$D$19)*10 -> 79342.9 | E19: C | F19: =+(D19*C19)/100 -> 0 | G19: =((FEEDERS!$G$100*4)/10+FEEDERS!$G$19)*10 -> 335.75 | H19: C | I19: =+(G19*C19)/100 -> 0 | J19: =+(((I19*$I$323)+(F19*(1+$E$323)))*(1+$C$329)) -> 0 | K19: =IF(J19=0,0,J19/C19) -> 0 | P19: 101 | Q19: #750 MCM Thhn Wire
B20: AL feed (ft) | D20: =((FEEDERS!$D$119*4)/10+FEEDERS!$D$19)*11 -> 34010.79 | E20: C | F20: =+(D20*C20)/100 -> 0 | G20: =((FEEDERS!$G$119*4)/10+FEEDERS!$G$19)*11 -> 347.325 | H20: C | I20: =+(G20*C20)/100 -> 0 | J20: =+(((I20*$I$323)+(F20*(1+$E$323)))*(1+$C$329)) -> 0 | K20: =IF(J20=0,0,J20/C20) -> 0
A21: 3000A., 277/480V., 3PH. Main switchboard w/ meter | D21: 30000 | E21: E | F21: =+D21*C21 -> 0 | G21: 104 | H21: E | I21: =+G21*C21 -> 0 | J21: =+(((I21*$I$323)+(F21*(1+$E$323)))*(1+$C$329)) -> 0 | K21: =IF(J21=0,0,J21/C21) -> 0
B22: CU feed (ft) | D22: =((FEEDERS!$D$99*4)/10+FEEDERS!$D$19)*8 -> 53390.96 | E22: C | F22: =+(D22*C22)/100 -> 0 | G22: =((FEEDERS!$G$99*4)/10+FEEDERS!$G$19)*8 -> 255.8 | H22: C | I22: =+(G22*C22)/100 -> 0 | J22: =+(((I22*$I$323)+(F22*(1+$E$323)))*(1+$C$329)) -> 0 | K22: =IF(J22=0,0,J22/C22) -> 0
B23: AL feed (ft) | D23: =((FEEDERS!$D$119*4)/10+FEEDERS!$D$19)*8 -> 24735.12 | E23: C | F23: =+(D23*C23)/100 -> 0 | G23: =((FEEDERS!$G$119*4)/10+FEEDERS!$G$19)*8 -> 252.6 | H23: C | I23: =+(G23*C23)/100 -> 0 | J23: =+(((I23*$I$323)+(F23*(1+$E$323)))*(1+$C$329)) -> 0 | K23: =IF(J23=0,0,J23/C23) -> 0
A24: 2500A., 277/480V., 3PH. Main switchboard w/ meter | D24: 25000 | E24: E | F24: =+D24*C24 -> 0 | G24: 82 | H24: E | I24: =+G24*C24 -> 0 | J24: =+(((I24*$I$323)+(F24*(1+$E$323)))*(1+$C$329)) -> 0 | K24: =IF(J24=0,0,J24/C24) -> 0
B25: CU feed (ft) | D25: =((FEEDERS!$D$100*4)/10+FEEDERS!$D$19)*6 -> 47605.74 | E25: C | F25: =+(D25*C25)/100 -> 0 | G25: =((FEEDERS!$G$100*4)/10+FEEDERS!$G$19)*6 -> 201.45 | H25: C | I25: =+(G25*C25)/100 -> 0 | J25: =+(((I25*$I$323)+(F25*(1+$E$323)))*(1+$C$329)) -> 0 | K25: =IF(J25=0,0,J25/C25) -> 0
B26: AL feed (ft) | D26: =((FEEDERS!$D$119*4)/10+FEEDERS!$D$19)*7 -> 21643.23 | E26: C | F26: =+(D26*C26)/100 -> 0 | G26: =((FEEDERS!$G$119*4)/10+FEEDERS!$G$19)*7 -> 221.025 | H26: C | I26: =+(G26*C26)/100 -> 0 | J26: =+(((I26*$I$323)+(F26*(1+$E$323)))*(1+$C$329)) -> 0 | K26: =IF(J26=0,0,J26/C26) -> 0 | U26: k
A27: 2000A., 277/480V., 3PH. Main switchboard w/ meter | D27: 23000 | E27: E | F27: =+D27*C27 -> 0 | G27: 66 | H27: E | I27: =+G27*C27 -> 0 | J27: =+(((I27*$I$323)+(F27*(1+$E$323)))*(1+$C$329)) -> 0 | K27: =IF(J27=0,0,J27/C27) -> 0
B28: CU feed (ft) | D28: =((FEEDERS!$D$100*4)/10+FEEDERS!$D$19)*5 -> 39671.45 | E28: C | F28: =+(D28*C28)/100 -> 0 | G28: =((FEEDERS!$G$100*4)/10+FEEDERS!$G$19)*5 -> 167.875 | H28: C | I28: =+(G28*C28)/100 -> 0 | J28: =+(((I28*$I$323)+(F28*(1+$E$323)))*(1+$C$329)) -> 0 | K28: =IF(J28=0,0,J28/C28) -> 0
B29: AL feed (ft) | D29: =((FEEDERS!$D$118*4)/10+FEEDERS!$D$19)*6 -> 16876.86 | E29: C | F29: =+(D29*C29)/100 -> 0 | G29: =((FEEDERS!$G$118*4)/10+FEEDERS!$G$19)*6 -> 182.25 | H29: C | I29: =+(G29*C29)/100 -> 0 | J29: =+(((I29*$I$323)+(F29*(1+$E$323)))*(1+$C$329)) -> 0 | K29: =IF(J29=0,0,J29/C29) -> 0
A30: 1600A., 277/480V., 3PH. Main switchboard w/ meter | D30: 20000 | E30: E | F30: =+D30*C30 -> 0 | G30: 55 | H30: E | I30: =+G30*C30 -> 0 | J30: =+(((I30*$I$323)+(F30*(1+$E$323)))*(1+$C$329)) -> 0 | K30: =IF(J30=0,0,J30/C30) -> 0
B31: CU feed (ft) | D31: =((FEEDERS!$D$100*4)/10+FEEDERS!$D$19)*4 -> 31737.16 | E31: C | F31: =+(D31*C31)/100 -> 0 | G31: =((FEEDERS!$G$100*4)/10+FEEDERS!$G$19)*4 -> 134.3 | H31: C | I31: =+(G31*C31)/100 -> 0 | J31: =+(((I31*$I$323)+(F31*(1+$E$323)))*(1+$C$329)) -> 0 | K31: =IF(J31=0,0,J31/C31) -> 0
B32: AL feed (ft) | D32: =((FEEDERS!$D$118*4)/10+FEEDERS!$D$19)*5 -> 14064.05 | E32: C | F32: =+(D32*C32)/100 -> 0 | G32: =((FEEDERS!$G$118*4)/10+FEEDERS!$G$19)*5 -> 151.875 | H32: C | I32: =+(G32*C32)/100 -> 0 | J32: =+(((I32*$I$323)+(F32*(1+$E$323)))*(1+$C$329)) -> 0 | K32: =IF(J32=0,0,J32/C32) -> 0
A33: 1200A., 277/480V., 3PH. Main distribution board w/ ct/meter | D33: 17000 | E33: E | F33: =+D33*C33 -> 0 | G33: 51 | H33: E | I33: =+G33*C33 -> 0 | J33: =+(((I33*$I$323)+(F33*(1+$E$323)))*(1+$C$329)) -> 0 | K33: =IF(J33=0,0,J33/C33) -> 0
B34: CU feed (ft) | D34: =((FEEDERS!$D$100*4)/10+FEEDERS!$D$19)*3 -> 23802.87 | E34: C | F34: =+(D34*C34)/100 -> 0 | G34: =((FEEDERS!$G$100*4)/10+FEEDERS!$G$19)*3 -> 100.725 | H34: C | I34: =+(G34*C34)/100 -> 0 | J34: =+(((I34*$I$323)+(F34*(1+$E$323)))*(1+$C$329)) -> 0 | K34: =IF(J34=0,0,J34/C34) -> 0
B35: AL feed (ft) | D35: =((FEEDERS!$D$117*4)/10+FEEDERS!$D$17)*4 -> 8974.88 | E35: C | F35: =+(D35*C35)/100 -> 0 | G35: =((FEEDERS!$G$117*4)/10+FEEDERS!$G$17)*4 -> 95.6 | H35: C | I35: =+(G35*C35)/100 -> 0 | J35: =+(((I35*$I$323)+(F35*(1+$E$323)))*(1+$C$329)) -> 0 | K35: =IF(J35=0,0,J35/C35) -> 0
A36: 1000A., 277/480V., 3PH. Main distribution board w/ ct/meter | D36: 15000 | E36: E | F36: =+D36*C36 -> 0 | G36: 41 | H36: E | I36: =+G36*C36 -> 0 | J36: =+(((I36*$I$323)+(F36*(1+$E$323)))*(1+$C$329)) -> 0 | K36: =IF(J36=0,0,J36/C36) -> 0
B37: CU feed (ft) | D37: =((FEEDERS!$D$98*4)/10+FEEDERS!$D$17)*3 -> 16171.08 | E37: C | F37: =+(D37*C37)/100 -> 0 | G37: =((FEEDERS!$G$98*4)/10+FEEDERS!$G$17)*3 -> 75.3 | H37: C | I37: =+(G37*C37)/100 -> 0 | J37: =+(((I37*$I$323)+(F37*(1+$E$323)))*(1+$C$329)) -> 0 | K37: =IF(J37=0,0,J37/C37) -> 0
B38: AL feed (ft) | D38: =((FEEDERS!$D$118*4)/10+FEEDERS!$D$19)*3 -> 8438.43 | E38: C | F38: =+(D38*C38)/100 -> 0 | G38: =((FEEDERS!$G$118*4)/10+FEEDERS!$G$19)*3 -> 91.125 | H38: C | I38: =+(G38*C38)/100 -> 0 | J38: =+(((I38*$I$323)+(F38*(1+$E$323)))*(1+$C$329)) -> 0 | K38: =IF(J38=0,0,J38/C38) -> 0
A39: 800A., 277/480V., 3PH. Distribution board w/ feed | D39: 9000 | E39: E | F39: =+D39*C39 -> 0 | G39: 33 | H39: E | I39: =+G39*C39 -> 0 | J39: =+(((I39*$I$323)+(F39*(1+$E$323)))*(1+$C$329)) -> 0 | K39: =IF(J39=0,0,J39/C39) -> 0
B40: 600 CU feed (ft) | D40: =((FEEDERS!$D$100*4)/10+FEEDERS!$D$19)*2 -> 15868.58 | E40: C | F40: =+(D40*C40)/100 -> 0 | G40: =((FEEDERS!$G$100*4)/10+FEEDERS!$G$19)*2 -> 67.15 | H40: C | I40: =+(G40*C40)/100 -> 0 | J40: =+(((I40*$I$323)+(F40*(1+$E$323)))*(1+$C$329)) -> 0 | K40: =IF(J40=0,0,J40/C40) -> 0
...

Sheet FEEDERS
A1: Project | D1: Project# | F1: DATE: | G1: Prepared BY
A2: Job Name | D2: KM05 | F2: Todays Date | G2: KM
A3: Job Location
A4: G.C.
A5: Contact Name | M5: ELYSIA SHEET
A6: Telephone - Fax | M6: TAKE HIGHEST PRICE | S6: Aluminum Pricing
M7: PER 100 | Q7: Prevoius Price | S7: PER 1000
A8: MATERIAL | C8: QTY | D8: MAT UNIT | E8: per | F8: EXTENSION | G8: LBR UNIT | H8: per | I8: EXTENSION | J8: TOTAL | K8: $$/QTY | M8: 1/2-EMT | O8: 72 | Q8: 70 | R8: =(O8-Q8)/Q8 -> 0.028571429 | S8: #1 | U8: 450
A9: EMT Set Screw UNIT | J9: =+(((I9*$I$125)+(F9*(1+$E$125)))*(1+$C$131)) -> 0 | K9: =IF(J9=0,0,J9/C9) -> 0 | M9: 1/2-HW | O9: 338 | Q9: 331 | R9: =(O9-Q9)/Q9 -> 0.021148036 | S9: #1/0 | U9: 500
A10: 1/2" SS EMT Unit | B10: 0.5 | C10: 1 | D10: =O8*B10+O8 -> 108 | E10: C | F10: =+(D10*C10)/100 -> 1.08 | G10: 4.67 | H10: C | I10: =+(G10*C10)/100 -> 0.0467 | J10: =+(((I10*$I$125)+(F10*(1+$E$125)))*(1+$C$131)) -> 5.7673 | K10: =IF(J10=0,0,J10/C10) -> 5.7673 | M10: 1/2-IMC | O10: 203 | Q10: 199 | R10: =(O10-Q10)/Q10 -> 0.020100503 | S10: #2/0 | U10: 600
A11: 3/4" SS EMT Unit | B11: 0.45 | C11: 1 | D11: =O12*B11+O12 -> 184.15 | E11: C | F11: =+(D11*C11)/100 -> 1.8415 | G11: 4.96 | H11: C | I11: =+(G11*C11)/100 -> 0.0496 | J11: =+(((I11*$I$125)+(F11*(1+$E$125)))*(1+$C$131)) -> 6.8910538 | K11: =IF(J11=0,0,J11/C11) -> 6.8910538 | M11: 1/2-PVC40 | O11: 89 | Q11: 89 | R11: =(O11-Q11)/Q11 -> 0 | S11: #3/0 | U11: 700
A12: 1" SS EMT Unit | B12: 0.4 | C12: 1 | D12: =O16+B12*O16 -> 312.2 | E12: C | F12: =+(D12*C12)/100 -> 3.122 | G12: 6.938 | H12: C | I12: =+(G12*C12)/100 -> 0.06938 | J12: =+(((I12*$I$125)+(F12*(1+$E$125)))*(1+$C$131)) -> 10.241245 | K12: =IF(J12=0,0,J12/C12) -> 10.241245 | M12: 3/4-EMT | O12: 127 | Q12: 124 | R12: =(O12-Q12)/Q12 -> 0.024193548 | S12: #4/0 | U12: 800
A13: 1-1/4" SS EMT Unit | B13: 0.4 | C13: 1 | D13: =O20*B13+O20 -> 508.2 | E13: C | F13: =+(D13*C13)/100 -> 5.082 | G13: 8.182 | H13: C | I13: =+(G13*C13)/100 -> 0.08182 | J13: =+(((I13*$I$125)+(F13*(1+$E$125)))*(1+$C$131)) -> 13.621265 | K13: =IF(J13=0,0,J13/C13) -> 13.621265 | M13: 3/4-HW | O13: 346 | Q13: 339 | R13: =(O13-Q13)/Q13 -> 0.020648968 | S13: 250 MCM | U13: 950
A14: 1-1/2" SS EMT Unit | B14: 0.4 | C14: 1 | D14: =O24*B14+O24 -> 621.6 | E14: C | F14: =+(D14*C14)/100 -> 6.216 | G14: 9.542 | H14: C | I14: =+(G14*C14)/100 -> 0.09542 | J14: =+(((I14*$I$125)+(F14*(1+$E$125)))*(1+$C$131)) -> 16.2043 | K14: =IF(J14=0,0,J14/C14) -> 16.2043 | M14: 3/4-IMC | O14: 239 | Q14: 234 | R14: =(O14-Q14)/Q14 -> 0.021367521 | S14: 300 MCM | U14: 1300
A15: 2" SS EMT Unit | B15: 0.35 | C15: 1 | D15: =O28*B15+O28 -> 700.65 | E15: C | F15: =+(D15*C15)/100 -> 7.0065 | G15: 11.213 | H15: C | I15: =+(G15*C15)/100 -> 0.11213 | J15: =+(((I15*$I$125)+(F15*(1+$E$125)))*(1+$C$131)) -> 18.713406 | K15: =IF(J15=0,0,J15/C15) -> 18.713406 | M15: 3/4-PVC40 | O15: 108 | Q15: 108 | R15: =(O15-Q15)/Q15 -> 0 | S15: 350 MCM | U15: 1350
A16: 2-1/2" SS EMT Unit | B16: 0.3 | C16: 1 | D16: =O32*B16+O32 -> 1024.4 | E16: C | F16: =+(D16*C16)/100 -> 10.244 | G16: 12.1 | H16: C | I16: =+(G16*C16)/100 -> 0.121 | J16: =+(((I16*$I$125)+(F16*(1+$E$125)))*(1+$C$131)) -> 23.15201 | K16: =IF(J16=0,0,J16/C16) -> 23.15201 | M16: 1-EMT | O16: 223 | Q16: 219 | R16: =(O16-Q16)/Q16 -> 0.01826484 | S16: 400 MM | U16: 1550
A17: 3" SS EMT Unit | B17: 0.25 | C17: 1 | D17: =O36*B17+O36 -> 1250 | E17: C | F17: =+(D17*C17)/100 -> 12.5 | G17: 13.5 | H17: C | I17: =+(G17*C17)/100 -> 0.135 | J17: =+(((I17*$I$125)+(F17*(1+$E$125)))*(1+$C$131)) -> 27.01125 | K17: =IF(J17=0,0,J17/C17) -> 27.01125 | M17: 1-HW | O17: 552 | Q17: 540 | R17: =(O17-Q17)/Q17 -> 0.022222222 | S17: 500 MCM | U17: 1700
A18: 3-1/2" SS EMT Unit | B18: 0.2 | C18: 1 | D18: =O40*B18+O40 -> 1584 | E18: C | F18: =+(D18*C18)/100 -> 15.84 | G18: 16.355 | H18: C | I18: =+(G18*C18)/100 -> 0.16355 | J18: =+(((I18*$I$125)+(F18*(1+$E$125)))*(1+$C$131)) -> 33.4915 | K18: =IF(J18=0,0,J18/C18) -> 33.4915 | M18: 1-IMC | O18: 367 | Q18: 359 | R18: =(O18-Q18)/Q18 -> 0.022284123 | S18: 600 MCM | U18: 2200
A19: 4" SS EMT Unit | B19: 0.15 | C19: 1 | D19: =O44*B19+O44 -> 1553.65 | E19: C | F19: =+(D19*C19)/100 -> 15.5365 | G19: 18.775 | H19: C | I19: =+(G19*C19)/100 -> 0.18775 | J19: =+(((I19*$I$125)+(F19*(1+$E$125)))*(1+$C$131)) -> 35.528491 | K19: =IF(J19=0,0,J19/C19) -> 35.528491 | M19: 1-PVC40 | O19: 164 | Q19: 164 | R19: =(O19-Q19)/Q19 -> 0 | S19: 750 MCM | U19: 2600
J20: =+(((I20*$I$125)+(F20*(1+$E$125)))*(1+$C$131)) -> 0 | K20: =IF(J20=0,0,J20/C20) -> 0 | M20: 1-1/4-EMT | O20: 363 | Q20: 356 | R20: =(O20-Q20)/Q20 -> 0.019662921 | S20: 900 MCM | U20: 3500
A21: EMT Compression UNIT | J21: =+(((I21*$I$125)+(F21*(1+$E$125)))*(1+$C$131)) -> 0 | K21: =IF(J21=0,0,J21/C21) -> 0 | M21: 1-1/4-HW | O21: 813 | Q21: 795 | R21: =(O21-Q21)/Q21 -> 0.022641509
A22: 1/2" COMP EMT Unit | B22: 0.6 | C22: 1 | D22: =O8*B22+O8 -> 115.2 | E22: C | F22: =+(D22*C22)/100 -> 1.152 | G22: 4.79 | H22: C | I22: =+(G22*C22)/100 -> 0.0479 | J22: =+(((I22*$I$125)+(F22*(1+$E$125)))*(1+$C$131)) -> 5.96428 | K22: =IF(J22=0,0,J22/C22) -> 5.96428 | M22: 1-1/4-IMC | O22: 515 | Q22: 504 | R22: =(O22-Q22)/Q22 -> 0.021825397
A23: 3/4" COMP EMT Unit | B23: 0.55 | C23: 1 | D23: =O12*B23+O12 -> 196.85 | E23: C | F23: =+(D23*C23)/100 -> 1.9685 | G23: 5.065 | H23: C | I23: =+(G23*C23)/100 -> 0.05065 | J23: =+(((I23*$I$125)+(F23*(1+$E$125)))*(1+$C$131)) -> 7.1339713 | K23: =IF(J23=0,0,J23/C23) -> 7.1339713 | M23: 1-1/4-PVC40 | O23: 222 | Q23: 222 | R23: =(O23-Q23)/Q23 -> 0
A24: 1" COMP EMT Unit | B24: 0.5 | C24: 1 | D24: =O16*B24+O16 -> 334.5 | E24: C | F24: =+(D24*C24)/100 -> 3.345 | G24: 6.905 | H24: C | I24: =+(G24*C24)/100 -> 0.06905 | J24: =+(((I24*$I$125)+(F24*(1+$E$125)))*(1+$C$131)) -> 10.454763 | K24: =IF(J24=0,0,J24/C24) -> 10.454763 | M24: 1-1/2-EMT | O24: 444 | Q24: 435 | R24: =(O24-Q24)/Q24 -> 0.020689655
A25: 1-1/4" COMP EMT Unit | B25: 0.45 | C25: 1 | D25: =O22*B25+O22 -> 746.75 | E25: C | F25: =+(D25*C25)/100 -> 7.4675 | G25: 8.282 | H25: C | I25: =+(G25*C25)/100 -> 0.08282 | J25: =+(((I25*$I$125)+(F25*(1+$E$125)))*(1+$C$131)) -> 16.349279 | K25: =IF(J25=0,0,J25/C25) -> 16.349279 | M25: 1-1/2-HW | O25: 914 | Q25: 895 | R25: =(O25-Q25)/Q25 -> 0.02122905
A26: 1-1/2" COMP EMT Unit | B26: 0.4 | C26: 1 | D26: =O24*B26+O24 -> 621.6 | E26: C | F26: =+(D26*C26)/100 -> 6.216 | G26: 9.663 | H26: C | I26: =+(G26*C26)/100 -> 0.09663 | J26: =+(((I26*$I$125)+(F26*(1+$E$125)))*(1+$C$131)) -> 16.32288 | K26: =IF(J26=0,0,J26/C26) -> 16.32288 | M26: 1-1/2-IMC | O26: 641 | Q26: 627 | R26: =(O26-Q26)/Q26 -> 0.022328549
A27: 2" COMP EMT Unit | B27: 0.35 | C27: 1 | D27: =O28*B27+O28 -> 700.65 | E27: C | F27: =+(D27*C27)/100 -> 7.0065 | G27: 11.392 | H27: C | I27: =+(G27*C27)/100 -> 0.11392 | J27: =+(((I27*$I$125)+(F27*(1+$E$125)))*(1+$C$131)) -> 18.888826 | K27: =IF(J27=0,0,J27/C27) -> 18.888826 | M27: 1-1/2-PVC40 | O27: 257 | Q27: 257 | R27: =(O27-Q27)/Q27 -> 0
A28: 2-1/2" COMP EMT Unit | B28: 0.3 | C28: 1 | D28: =O32*B28+O32 -> 1024.4 | E28: C | F28: =+(D28*C28)/100 -> 10.244 | G28: 12.23 | H28: C | I28: =+(G28*C28)/100 -> 0.1223 | J28: =+(((I28*$I$125)+(F28*(1+$E$125)))*(1+$C$131)) -> 23.27941 | K28: =IF(J28=0,0,J28/C28) -> 23.27941 | M28: 2-EMT | O28: 519 | Q28: 509 | R28: =(O28-Q28)/Q28 -> 0.019646365
A29: 3" COMP EMT Unit | B29: 0.25 | C29: 1 | D29: =O36*B29+O36 -> 1250 | E29: C | F29: =+(D29*C29)/100 -> 12.5 | G29: 13.65 | H29: C | I29: =+(G29*C29)/100 -> 0.1365 | J29: =+(((I29*$I$125)+(F29*(1+$E$125)))*(1+$C$131)) -> 27.15825 | K29: =IF(J29=0,0,J29/C29) -> 27.15825 | M29: 2-HW | O29: 1121 | Q29: 1097 | R29: =(O29-Q29)/Q29 -> 0.021877849
A30: 3-1/2" COMP EMT Unit | B30: 0.2 | C30: 1 | D30: =O40*B30+O40 -> 1584 | E30: C | F30: =+(D30*C30)/100 -> 15.84 | G30: 16.535 | H30: C | I30: =+(G30*C30)/100 -> 0.16535 | J30: =+(((I30*$I$125)+(F30*(1+$E$125)))*(1+$C$131)) -> 33.6679 | K30: =IF(J30=0,0,J30/C30) -> 33.6679 | M30: 2-IMC | O30: 802 | Q30: 785 | R30: =(O30-Q30)/Q30 -> 0.021656051
A31: 4" COMP EMT Unit | B31: 0.3 | C31: 1 | D31: =O44*B31+O44 -> 1756.3 | E31: C | F31: =+(D31*C31)/100 -> 17.563 | G31: 18.975 | H31: C | I31: =+(G31*C31)/100 -> 0.18975 | J31: =+(((I31*$I$125)+(F31*(1+$E$125)))*(1+$C$131)) -> 37.958708 | K31: =IF(J31=0,0,J31/C31) -> 37.958708 | M31: 2-PVC40 | O31: 326 | Q31: 326 | R31: =(O31-Q31)/Q31 -> 0
M32: 2-1/2-EMT | O32: 788 | Q32: 772 | R32: =(O32-Q32)/Q32 -> 0.020725389 | S32: Romex labor rate / ft
A33: HW Unit | J33: =+(((I33*$I$125)+(F33*(1+$E$125)))*(1+$C$131)) -> 0 | K33: =IF(J33=0,0,J33/C33) -> 0 | M33: 2-1/2-HW | O33: 2112 | Q33: 2068 | R33: =(O33-Q33)/Q33 -> 0.021276596 | S33: 14/2: .012 .015 .018 | V33: 390 | W33: 456
A34: 1/2" HW Unit | B34: 0.5 | C34: 1 | D34: =O9*B34+O9 -> 507 | E34: C | F34: =+(D34*C34)/100 -> 5.07 | G34: 9.224 | H34: C | I34: =+(G34*C34)/100 -> 0.09224 | J34: =+(((I34*$I$125)+(F34*(1+$E$125)))*(1+$C$131)) -> 14.629195 | K34: =IF(J34=0,0,J34/C34) -> 14.629195 | M34: 2-1/2-IMC | O34: 1591 | Q34: 1557 | R34: =(O34-Q34)/Q34 -> 0.021836866 | S34: 12/2: .012 .015 .018 | W34: 675
A35: 3/4" HW Unit | B35: 0.45 | C35: 1 | D35: =O13*B35+O13 -> 501.7 | E35: C | F35: =+(D35*C35)/100 -> 5.017 | G35: 9.853 | H35: C | I35: =+(G35*C35)/100 -> 0.09853 | J35: =+(((I35*$I$125)+(F35*(1+$E$125)))*(1+$C$131)) -> 15.187182 | K35: =IF(J35=0,0,J35/C35) -> 15.187182 | M35: 2-1/2-PVC40 | O35: 506 | Q35: 506 | R35: =(O35-Q35)/Q35 -> 0 | S35: 10/2: .012 .015 .018
A36: 1" HW Unit | B36: 0.4 | C36: 1 | D36: =O17*B36+O17 -> 772.8 | E36: C | F36: =+(D36*C36)/100 -> 7.728 | G36: 10.823 | H36: C | I36: =+(G36*C36)/100 -> 0.10823 | J36: =+(((I36*$I$125)+(F36*(1+$E$125)))*(1+$C$131)) -> 19.12666 | K36: =IF(J36=0,0,J36/C36) -> 19.12666 | M36: 3-EMT | O36: 1000 | Q36: 979 | R36: =(O36-Q36)/Q36 -> 0.02145046 | S36: 14/3: .012 .015 .018 | W36: 637
A37: 1-1/4" HW Unit | B37: 0.4 | C37: 1 | D37: =O21*B37+O21 -> 1138.2 | E37: C | F37: =+(D37*C37)/100 -> 11.382 | G37: 14.625 | H37: C | I37: =+(G37*C37)/100 -> 0.14625 | J37: =+(((I37*$I$125)+(F37*(1+$E$125)))*(1+$C$131)) -> 26.881155 | K37: =IF(J37=0,0,J37/C37) -> 26.881155 | M37: 3-HW | O37: 2395 | Q37: 2344 | R37: =(O37-Q37)/Q37 -> 0.021757679 | S37: 12/3: .012 .015 .018 | W37: 927
A38: 1-1/2" HW Unit | B38: 0.4 | C38: 1 | D38: =O25*B38+O25 -> 1279.6 | E38: C | F38: =+(D38*C38)/100 -> 12.796 | G38: 16.46 | H38: C | I38: =+(G38*C38)/100 -> 0.1646 | J38: =+(((I38*$I$125)+(F38*(1+$E$125)))*(1+$C$131)) -> 30.23839 | K38: =IF(J38=0,0,J38/C38) -> 30.23839 | M38: 3-IMC | O38: 2082 | Q38: 2038 | R38: =(O38-Q38)/Q38 -> 0.021589794 | S38: 10/3: .012 .015 .018 | W38: 1538
A39: 2" HW Unit | B39: 0.35 | C39: 1 | D39: =O33*B39+O33 -> 2851.2 | E39: C | F39: =+(D39*C39)/100 -> 28.512 | G39: 18.948 | H39: C | I39: =+(G39*C39)/100 -> 0.18948 | J39: =+(((I39*$I$125)+(F39*(1+$E$125)))*(1+$C$131)) -> 50.00352 | K39: =IF(J39=0,0,J39/C39) -> 50.00352 | M39: 3-PVC40 | O39: 615 | Q39: 615 | R39: =(O39-Q39)/Q39 -> 0
A40: 2-1/2" HW Unit | B40: 0.3 | C40: 1 | D40: =O33*B40+O33 -> 2745.6 | E40: C | F40: =+(D40*C40)/100 -> 27.456 | G40: 19.997 | H40: C | I40: =+(G40*C40)/100 -> 0.19997 | J40: =+(((I40*$I$125)+(F40*(1+$E$125)))*(1+$C$131)) -> 49.8673 | K40: =IF(J40=0,0,J40/C40) -> 49.8673 | M40: 3-1/2-EMT | O40: 1320 | Q40: 1292 | R40: =(O40-Q40)/Q40 -> 0.021671827
...

Sheet Copy
A1: Project | D1: Project# | F1: DATE: | G1: Prepared BY | N1: 10 | O1: 1/2" | P1: 83 | Q1: ﻿#12 Thhn Stranded | T1: 108 | U1: #1 Thhn Stranded
A2: Job Name | D2: KM05 | F2: Todays Date | G2: KM | N2: 11 | O2: 3/4" | P2: 84 | Q2: #10 Thhn Stranded | T2: 109 | U2: #1/0 Thhn Stranded
A3: Job Location | N3: 12 | O3: 1" | P3: 85 | Q3: #8 Thhn Stranded | T3: 110 | U3: #2/0 Thhn Stranded
A4: G.C. | N4: 13 | O4: 1-1/4" | P4: 86 | Q4: #6 Thhn Stranded | T4: 111 | U4: #3/0 Thhn Stranded
A5: Contact Name | N5: 14 | O5: 1-1/2" | P5: 87 | Q5: #4 Thhn Stranded | T5: 112 | U5: #4/0 Thhn Stranded
A6: Telephone - Fax | N6: 15 | O6: 2" | P6: 88 | Q6: #3 Thhn Stranded | T6: 113 | U6: #250 MCM Thhn Wire
N7: 16 | O7: 2-1/2" | P7: 89 | Q7: #2 Thhn Stranded | T7: 114 | U7: #300 MCM Thhn Wire
A8: MATERIAL | C8: QTY | D8: MAT UNIT | E8: per | F8: EXTENSION | G8: LBR UNIT | H8: per | I8: EXTENSION | J8: TOTAL | K8: $$/QTY | N8: 17 | O8: 3" | P8: 90 | Q8: #1 Thhn Stranded | T8: 115 | U8: #350 MCM Thhn Wire
N9: 18 | O9: 3-1/2" | P9: 91 | Q9: #1/0 Thhn Stranded | T9: 116 | U9: #400 MCM Thhn Wire
N10: 19 | O10: 4" | P10: 92 | Q10: #2/0 Thhn Stranded | T10: 117 | U10: #500 MCM Thhn Wire
A11: TEMP POWER | B11: =SUM(J12:J14) -> 0 | P11: 93 | Q11: #3/0 Thhn Stranded | T11: 118 | U11: #600 MCM Thhn Wire
A12: Temp power from ComEd permanent power | D12: =F327/100 -> 8285.2 | E12: Lot | F12: =+D12*C12 -> 0 | G12: =F327/10000 -> 82.852 | H12: Lot | I12: =+G12*C12 -> 0 | J12: =+(((I12*$I$324)+(F12*(1+$E$324)))*(1+$C$330)) -> 0 | K12: =IF(J12=0,0,J12/C12) -> 0 | P12: 94 | Q12: #4/0 Thhn Stranded | T12: 119 | U12: #750 MCM Thhn Wire
A13: Hook up of construction trailer | D13: 1500 | E13: Lot | F13: =+D13*C13 -> 0 | G13: 30 | H13: Lot | I13: =+G13*C13 -> 0 | J13: =+(((I13*$I$324)+(F13*(1+$E$324)))*(1+$C$330)) -> 0 | K13: =IF(J13=0,0,J13/C13) -> 0 | P13: 95 | Q13: #250 MCM Thhn Wire | T13: 120 | U13: #900 MCM Thhn Wire
P14: 96 | Q14: #300 MCM Thhn Wire
A15: ELECTRICAL SERVICE & DISTRIBUTION | B15: =SUM(J16:J158) -> 600.58381 | K15: =IF(J15=0,0,J15/C15) -> 0 | P15: 97 | Q15: #350 MCM Thhn Wire
A16: ComEd pad | D16: 2000 | E16: E | F16: =+D16*C16 -> 0 | G16: 10 | H16: E | I16: =+G16*C16 -> 0 | J16: =+(((I16*$I$324)+(F16*(1+$E$324)))*(1+$C$330)) -> 0 | K16: =IF(J16=0,0,J16/C16) -> 0 | P16: 98 | Q16: #400 MCM Thhn Wire
A17: Rework existing panel for new loads | D17: 400 | E17: E | F17: =+D17*C17 -> 0 | G17: 4 | H17: E | I17: =+G17*C17 -> 0 | J17: =+(((I17*$I$324)+(F17*(1+$E$324)))*(1+$C$330)) -> 0 | K17: =IF(J17=0,0,J17/C17) -> 0 | P17: 99 | Q17: #500 MCM Thhn Wire
A18: 4000A., 277/480V., 3PH. Main switchboard w/ meter | D18: 35000 | E18: E | F18: =+D18*C18 -> 0 | G18: 124 | H18: E | I18: =+G18*C18 -> 0 | J18: =+(((I18*$I$324)+(F18*(1+$E$324)))*(1+$C$330)) -> 0 | K18: =IF(J18=0,0,J18/C18) -> 0 | P18: 100 | Q18: #600 MCM Thhn Wire
B19: CU feed (ft) | D19: =((FEEDERS!$D$100*4)/10+FEEDERS!$D$19)*10 -> 79342.9 | E19: C | F19: =+(D19*C19)/100 -> 0 | G19: =((FEEDERS!$G$100*4)/10+FEEDERS!$G$19)*10 -> 335.75 | H19: C | I19: =+(G19*C19)/100 -> 0 | J19: =+(((I19*$I$324)+(F19*(1+$E$324)))*(1+$C$330)) -> 0 | K19: =IF(J19=0,0,J19/C19) -> 0 | P19: 101 | Q19: #750 MCM Thhn Wire
B20: AL feed (ft) | D20: =((FEEDERS!$D$119*4)/10+FEEDERS!$D$19)*11 -> 34010.79 | E20: C | F20: =+(D20*C20)/100 -> 0 | G20: =((FEEDERS!$G$119*4)/10+FEEDERS!$G$19)*11 -> 347.325 | H20: C | I20: =+(G20*C20)/100 -> 0 | J20: =+(((I20*$I$324)+(F20*(1+$E$324)))*(1+$C$330)) -> 0 | K20: =IF(J20=0,0,J20/C20) -> 0
A21: 3000A., 277/480V., 3PH. Main switchboard w/ meter | D21: 30000 | E21: E | F21: =+D21*C21 -> 0 | G21: 104 | H21: E | I21: =+G21*C21 -> 0 | J21: =+(((I21*$I$324)+(F21*(1+$E$324)))*(1+$C$330)) -> 0 | K21: =IF(J21=0,0,J21/C21) -> 0
B22: CU feed (ft) | D22: =((FEEDERS!$D$99*4)/10+FEEDERS!$D$19)*8 -> 53390.96 | E22: C | F22: =+(D22*C22)/100 -> 0 | G22: =((FEEDERS!$G$99*4)/10+FEEDERS!$G$19)*8 -> 255.8 | H22: C | I22: =+(G22*C22)/100 -> 0 | J22: =+(((I22*$I$324)+(F22*(1+$E$324)))*(1+$C$330)) -> 0 | K22: =IF(J22=0,0,J22/C22) -> 0
B23: AL feed (ft) | D23: =((FEEDERS!$D$119*4)/10+FEEDERS!$D$19)*8 -> 24735.12 | E23: C | F23: =+(D23*C23)/100 -> 0 | G23: =((FEEDERS!$G$119*4)/10+FEEDERS!$G$19)*8 -> 252.6 | H23: C | I23: =+(G23*C23)/100 -> 0 | J23: =+(((I23*$I$324)+(F23*(1+$E$324)))*(1+$C$330)) -> 0 | K23: =IF(J23=0,0,J23/C23) -> 0
A24: 2500A., 277/480V., 3PH. Main switchboard w/ meter | D24: 25000 | E24: E | F24: =+D24*C24 -> 0 | G24: 82 | H24: E | I24: =+G24*C24 -> 0 | J24: =+(((I24*$I$324)+(F24*(1+$E$324)))*(1+$C$330)) -> 0 | K24: =IF(J24=0,0,J24/C24) -> 0
B25: CU feed (ft) | D25: =((FEEDERS!$D$100*4)/10+FEEDERS!$D$19)*6 -> 47605.74 | E25: C | F25: =+(D25*C25)/100 -> 0 | G25: =((FEEDERS!$G$100*4)/10+FEEDERS!$G$19)*6 -> 201.45 | H25: C | I25: =+(G25*C25)/100 -> 0 | J25: =+(((I25*$I$324)+(F25*(1+$E$324)))*(1+$C$330)) -> 0 | K25: =IF(J25=0,0,J25/C25) -> 0
B26: AL feed (ft) | D26: =((FEEDERS!$D$119*4)/10+FEEDERS!$D$19)*7 -> 21643.23 | E26: C | F26: =+(D26*C26)/100 -> 0 | G26: =((FEEDERS!$G$119*4)/10+FEEDERS!$G$19)*7 -> 221.025 | H26: C | I26: =+(G26*C26)/100 -> 0 | J26: =+(((I26*$I$324)+(F26*(1+$E$324)))*(1+$C$330)) -> 0 | K26: =IF(J26=0,0,J26/C26) -> 0 | U26: k
A27: 2000A., 277/480V., 3PH. Main switchboard w/ meter | D27: 23000 | E27: E | F27: =+D27*C27 -> 0 | G27: 66 | H27: E | I27: =+G27*C27 -> 0 | J27: =+(((I27*$I$324)+(F27*(1+$E$324)))*(1+$C$330)) -> 0 | K27: =IF(J27=0,0,J27/C27) -> 0
B28: CU feed (ft) | D28: =((FEEDERS!$D$100*4)/10+FEEDERS!$D$19)*5 -> 39671.45 | E28: C | F28: =+(D28*C28)/100 -> 0 | G28: =((FEEDERS!$G$100*4)/10+FEEDERS!$G$19)*5 -> 167.875 | H28: C | I28: =+(G28*C28)/100 -> 0 | J28: =+(((I28*$I$324)+(F28*(1+$E$324)))*(1+$C$330)) -> 0 | K28: =IF(J28=0,0,J28/C28) -> 0
B29: AL feed (ft) | D29: =((FEEDERS!$D$118*4)/10+FEEDERS!$D$19)*6 -> 16876.86 | E29: C | F29: =+(D29*C29)/100 -> 0 | G29: =((FEEDERS!$G$118*4)/10+FEEDERS!$G$19)*6 -> 182.25 | H29: C | I29: =+(G29*C29)/100 -> 0 | J29: =+(((I29*$I$324)+(F29*(1+$E$324)))*(1+$C$330)) -> 0 | K29: =IF(J29=0,0,J29/C29) -> 0
A30: 1600A., 277/480V., 3PH. Main switchboard w/ meter | D30: 20000 | E30: E | F30: =+D30*C30 -> 0 | G30: 55 | H30: E | I30: =+G30*C30 -> 0 | J30: =+(((I30*$I$324)+(F30*(1+$E$324)))*(1+$C$330)) -> 0 | K30: =IF(J30=0,0,J30/C30) -> 0
B31: CU feed (ft) | D31: =((FEEDERS!$D$100*4)/10+FEEDERS!$D$19)*4 -> 31737.16 | E31: C | F31: =+(D31*C31)/100 -> 0 | G31: =((FEEDERS!$G$100*4)/10+FEEDERS!$G$19)*4 -> 134.3 | H31: C | I31: =+(G31*C31)/100 -> 0 | J31: =+(((I31*$I$324)+(F31*(1+$E$324)))*(1+$C$330)) -> 0 | K31: =IF(J31=0,0,J31/C31) -> 0
B32: AL feed (ft) | D32: =((FEEDERS!$D$118*4)/10+FEEDERS!$D$19)*5 -> 14064.05 | E32: C | F32: =+(D32*C32)/100 -> 0 | G32: =((FEEDERS!$G$118*4)/10+FEEDERS!$G$19)*5 -> 151.875 | H32: C | I32: =+(G32*C32)/100 -> 0 | J32: =+(((I32*$I$324)+(F32*(1+$E$324)))*(1+$C$330)) -> 0 | K32: =IF(J32=0,0,J32/C32) -> 0
A33: 1200A., 277/480V., 3PH. Main distribution board w/ ct/meter | D33: 17000 | E33: E | F33: =+D33*C33 -> 0 | G33: 51 | H33: E | I33: =+G33*C33 -> 0 | J33: =+(((I33*$I$324)+(F33*(1+$E$324)))*(1+$C$330)) -> 0 | K33: =IF(J33=0,0,J33/C33) -> 0
B34: CU feed (ft) | D34: =((FEEDERS!$D$100*4)/10+FEEDERS!$D$19)*3 -> 23802.87 | E34: C | F34: =+(D34*C34)/100 -> 0 | G34: =((FEEDERS!$G$100*4)/10+FEEDERS!$G$19)*3 -> 100.725 | H34: C | I34: =+(G34*C34)/100 -> 0 | J34: =+(((I34*$I$324)+(F34*(1+$E$324)))*(1+$C$330)) -> 0 | K34: =IF(J34=0,0,J34/C34) -> 0
B35: AL feed (ft) | D35: =((FEEDERS!$D$117*4)/10+FEEDERS!$D$17)*4 -> 8974.88 | E35: C | F35: =+(D35*C35)/100 -> 0 | G35: =((FEEDERS!$G$117*4)/10+FEEDERS!$G$17)*4 -> 95.6 | H35: C | I35: =+(G35*C35)/100 -> 0 | J35: =+(((I35*$I$324)+(F35*(1+$E$324)))*(1+$C$330)) -> 0 | K35: =IF(J35=0,0,J35/C35) -> 0
A36: 1000A., 277/480V., 3PH. Main distribution board w/ ct/meter | D36: 15000 | E36: E | F36: =+D36*C36 -> 0 | G36: 41 | H36: E | I36: =+G36*C36 -> 0 | J36: =+(((I36*$I$324)+(F36*(1+$E$324)))*(1+$C$330)) -> 0 | K36: =IF(J36=0,0,J36/C36) -> 0
B37: CU feed (ft) | D37: =((FEEDERS!$D$98*4)/10+FEEDERS!$D$17)*3 -> 16171.08 | E37: C | F37: =+(D37*C37)/100 -> 0 | G37: =((FEEDERS!$G$98*4)/10+FEEDERS!$G$17)*3 -> 75.3 | H37: C | I37: =+(G37*C37)/100 -> 0 | J37: =+(((I37*$I$324)+(F37*(1+$E$324)))*(1+$C$330)) -> 0 | K37: =IF(J37=0,0,J37/C37) -> 0
B38: AL feed (ft) | D38: =((FEEDERS!$D$118*4)/10+FEEDERS!$D$19)*3 -> 8438.43 | E38: C | F38: =+(D38*C38)/100 -> 0 | G38: =((FEEDERS!$G$118*4)/10+FEEDERS!$G$19)*3 -> 91.125 | H38: C | I38: =+(G38*C38)/100 -> 0 | J38: =+(((I38*$I$324)+(F38*(1+$E$324)))*(1+$C$330)) -> 0 | K38: =IF(J38=0,0,J38/C38) -> 0
A39: 800A., 277/480V., 3PH. Distribution board w/ feed | D39: 9000 | E39: E | F39: =+D39*C39 -> 0 | G39: 33 | H39: E | I39: =+G39*C39 -> 0 | J39: =+(((I39*$I$324)+(F39*(1+$E$324)))*(1+$C$330)) -> 0 | K39: =IF(J39=0,0,J39/C39) -> 0
B40: 600 CU feed (ft) | D40: =((FEEDERS!$D$100*4)/10+FEEDERS!$D$19)*2 -> 15868.58 | E40: C | F40: =+(D40*C40)/100 -> 0 | G40: =((FEEDERS!$G$100*4)/10+FEEDERS!$G$19)*2 -> 67.15 | H40: C | I40: =+(G40*C40)/100 -> 0 | J40: =+(((I40*$I$324)+(F40*(1+$E$324)))*(1+$C$330)) -> 0 | K40: =IF(J40=0,0,J40/C40) -> 0
...

Sheet Site
A1: STREETLIGHTING ESTIMATOR
A2: ESTIMATE #
A4: MATERIAL | B4: QTY | C4: MAT UNIT | D4: per | E4: EXTENSION | F4: LBR UNIT | G4: per | H4: EXTENSION
A6: Lighting Quote | B6: 1 | C6: =L15 -> 0 | D6: E | E6: =B6*C6 -> 0 | F6: 0 | G6: E | H6: =B6*F6 -> 0 | I6: =((((H6*$H$62)+(E6*(1+$C$62)))*(1+$B$67))*(1+$B$72)) -> 0 | J6: =IF(I6=0,0,I6/B6) -> 0
A7: S1 - Bollard | B7: 0 | C7: 50 | D7: E | E7: =B7*C7 -> 0 | F7: 5 | G7: E | H7: =B7*F7 -> 0 | I7: =((((H7*$H$62)+(E7*(1+$C$62)))*(1+$B$67))*(1+$B$72)) -> 0 | J7: =IF(I7=0,0,I7/B7) -> 0 | K7: 0 | L7: =K7*B7 -> 0
A8: S2 Light (One head) | B8: 0 | C8: 50 | D8: E | E8: =B8*C8 -> 0 | F8: 7 | G8: E | H8: =B8*F8 -> 0 | I8: =((((H8*$H$62)+(E8*(1+$C$62)))*(1+$B$67))*(1+$B$72)) -> 0 | J8: =IF(I8=0,0,I8/B8) -> 0 | K8: 0 | L8: =K8*B8 -> 0
A9: S6 Light (Two head) | B9: 0 | C9: 75 | D9: E | E9: =B9*C9 -> 0 | F9: 8.5 | G9: E | H9: =B9*F9 -> 0 | I9: =((((H9*$H$62)+(E9*(1+$C$62)))*(1+$B$67))*(1+$B$72)) -> 0 | J9: =IF(I9=0,0,I9/B9) -> 0 | K9: 0 | L9: =K9*B9 -> 0
A10: S7 Light (Three head) | B10: 0 | C10: 100 | D10: E | E10: =B10*C10 -> 0 | F10: 10 | G10: E | H10: =B10*F10 -> 0 | I10: =((((H10*$H$62)+(E10*(1+$C$62)))*(1+$B$67))*(1+$B$72)) -> 0 | J10: =IF(I10=0,0,I10/B10) -> 0 | K10: 0 | L10: =K10*B10 -> 0
A11: S7 Light (Four head) | B11: 0 | C11: 125 | D11: E | E11: =B11*C11 -> 0 | F11: 11.5 | G11: E | H11: =B11*F11 -> 0 | I11: =((((H11*$H$62)+(E11*(1+$C$62)))*(1+$B$67))*(1+$B$72)) -> 0 | J11: =IF(I11=0,0,I11/B11) -> 0 | K11: 0 | L11: =K11*B11 -> 0
A12: S8 Wall Pack | B12: 0 | C12: 50 | D12: E | E12: =B12*C12 -> 0 | F12: 5 | G12: E | H12: =B12*F12 -> 0 | I12: =((((H12*$H$62)+(E12*(1+$C$62)))*(1+$B$67))*(1+$B$72)) -> 0 | J12: =IF(I12=0,0,I12/B12) -> 0 | K12: 0 | L12: =K12*B12 -> 0
A13: Concrete base 2' X6' | B13: =SUM(B8:B11) -> 0 | C13: 500 | D13: E | E13: =B13*C13 -> 0 | F13: 8 | G13: E | H13: =B13*F13 -> 0 | I13: =((((H13*$H$62)+(E13*(1+$C$62)))*(1+$B$67))*(1+$B$72)) -> 0 | J13: =IF(I13=0,0,I13/B13) -> 0 | K13: SUB-TOTAL | L13: =SUM(L7:L12) -> 0
A14: Concrete base 12" X4' | B14: =B7 -> 0 | C14: 150 | D14: E | E14: =B14*C14 -> 0 | F14: 4 | G14: E | H14: =B14*F14 -> 0 | I14: =((((H14*$H$62)+(E14*(1+$C$62)))*(1+$B$67))*(1+$B$72)) -> 0 | J14: =IF(I14=0,0,I14/B14) -> 0 | K14: 0.05 | L14: =L13*K14 -> 0
A15: Helex 8" x 6' Chance T112 | B15: 0 | C15: 400 | D15: E | E15: =B15*C15 -> 0 | F15: 3 | G15: E | H15: =B15*F15 -> 0 | I15: =((((H15*$H$62)+(E15*(1+$C$62)))*(1+$B$67))*(1+$B$72)) -> 0 | J15: =IF(I15=0,0,I15/B15) -> 0 | K15: TOTAL | L15: =L14+L13 -> 0
A16: Fusing | B16: =B13+B14 -> 0 | C16: 20 | D16: E | E16: =B16*C16 -> 0 | F16: 0.15 | G16: E | H16: =B16*F16 -> 0 | I16: =((((H16*$H$62)+(E16*(1+$C$62)))*(1+$B$67))*(1+$B$72)) -> 0 | J16: =IF(I16=0,0,I16/B16) -> 0
A17: Grounding | B17: =B13+B14 -> 0 | C17: 35 | D17: E | E17: =B17*C17 -> 0 | F17: 0.3 | G17: E | H17: =B17*F17 -> 0 | I17: =((((H17*$H$62)+(E17*(1+$C$62)))*(1+$B$67))*(1+$B$72)) -> 0 | J17: =IF(I17=0,0,I17/B17) -> 0
A18: Trenching | B18: 0 | C18: 2 | D18: FT | E18: =B18*C18 -> 0 | F18: 8 | G18: C | H18: =B18*F18/100 -> 0 | I18: =((((H18*$H$62)+(E18*(1+$C$62)))*(1+$B$67))*(1+$B$72)) -> 0 | J18: =IF(I18=0,0,I18/B18) -> 0
A19: 1" GRC | B19: 0 | C19: 250 | D19: C | E19: =B19*C19/100 -> 0 | F19: 5 | G19: C | H19: =B19*F19/100 -> 0 | I19: =((((H19*$H$62)+(E19*(1+$C$62)))*(1+$B$67))*(1+$B$72)) -> 0 | J19: =IF(I19=0,0,I19/B19) -> 0
A20: 1-1/4" GRC | B20: 0 | C20: 350 | D20: C | E20: =B20*C20/100 -> 0 | F20: 5.5 | G20: C | H20: =B20*F20/100 -> 0 | I20: =((((H20*$H$62)+(E20*(1+$C$62)))*(1+$B$67))*(1+$B$72)) -> 0 | J20: =IF(I20=0,0,I20/B20) -> 0
A21: 1-1/2 GRC | B21: 0 | C21: 425 | D21: C | E21: =B21*C21/100 -> 0 | F21: 6.75 | G21: C | H21: =B21*F21/100 -> 0 | I21: =((((H21*$H$62)+(E21*(1+$C$62)))*(1+$B$67))*(1+$B$72)) -> 0 | J21: =IF(I21=0,0,I21/B21) -> 0
A22: 2" GRC | B22: 0 | C22: 500 | D22: C | E22: =B22*C22/100 -> 0 | F22: 7.75 | G22: C | H22: =B22*F22/100 -> 0 | I22: =((((H22*$H$62)+(E22*(1+$C$62)))*(1+$B$67))*(1+$B$72)) -> 0 | J22: =IF(I22=0,0,I22/B22) -> 0
A23: 3" GRC | B23: 0 | C23: 1100 | D23: C | E23: =B23*C23/100 -> 0 | F23: 12.25 | G23: C | H23: =B23*F23/100 -> 0 | I23: =((((H23*$H$62)+(E23*(1+$C$62)))*(1+$B$67))*(1+$B$72)) -> 0 | J23: =IF(I23=0,0,I23/B23) -> 0
A24: 4'' GRC | B24: 0 | C24: 1525 | D24: C | E24: =B24*C24/100 -> 0 | F24: 17.25 | G24: C | H24: =B24*F24/100 -> 0 | I24: =((((H24*$H$62)+(E24*(1+$C$62)))*(1+$B$67))*(1+$B$72)) -> 0 | J24: =IF(I24=0,0,I24/B24) -> 0
A25: 1" IMC | B25: 0 | C25: 180 | D25: C | E25: =B25*C25/100 -> 0 | F25: 5 | G25: C | H25: =B25*F25/100 -> 0 | I25: =((((H25*$H$62)+(E25*(1+$C$62)))*(1+$B$67))*(1+$B$72)) -> 0 | J25: =IF(I25=0,0,I25/B25) -> 0
A26: 1-1/4 IMC | B26: 0 | C26: 240 | D26: C | E26: =B26*C26/100 -> 0 | F26: 5.5 | G26: C | H26: =B26*F26/100 -> 0 | I26: =((((H26*$H$62)+(E26*(1+$C$62)))*(1+$B$67))*(1+$B$72)) -> 0 | J26: =IF(I26=0,0,I26/B26) -> 0
A27: 1-1/2 IMC | B27: 0 | C27: 310 | D27: C | E27: =B27*C27/100 -> 0 | F27: 7 | G27: C | H27: =B27*F27/100 -> 0 | I27: =((((H27*$H$62)+(E27*(1+$C$62)))*(1+$B$67))*(1+$B$72)) -> 0 | J27: =IF(I27=0,0,I27/B27) -> 0
A28: 2 IMC | B28: 0 | C28: 390 | D28: C | E28: =B28*C28/100 -> 0 | F28: 8 | G28: C | H28: =B28*F28/100 -> 0 | I28: =((((H28*$H$62)+(E28*(1+$C$62)))*(1+$B$67))*(1+$B$72)) -> 0 | J28: =IF(I28=0,0,I28/B28) -> 0
A29: 3" IMC | B29: 0 | C29: 950 | D29: C | E29: =B29*C29/100 -> 0 | F29: 12 | G29: C | H29: =B29*F29/100 -> 0 | I29: =((((H29*$H$62)+(E29*(1+$C$62)))*(1+$B$67))*(1+$B$72)) -> 0 | J29: =IF(I29=0,0,I29/B29) -> 0
A30: 4'' IMC | B30: 0 | C30: 1300 | D30: C | E30: =B30*C30/100 -> 0 | F30: 16.5 | G30: C | H30: =B30*F30/100 -> 0 | I30: =((((H30*$H$62)+(E30*(1+$C$62)))*(1+$B$67))*(1+$B$72)) -> 0 | J30: =IF(I30=0,0,I30/B30) -> 0
... A53: Spoils stockpile | B53: 0 | C53: 75 | D53: C | E53: =B53*C53/100 -> 0 | F53: 2 | G53: C | H53: =B53*F53/100 -> 0 | I53: =((((H53*$H$62)+(E53*(1+$C$62)))*(1+$B$67))*(1+$B$72)) -> 0 | J53: =IF(I53=0,0,I53/B53) -> 0
A54: Spoil removal | B54: 0 | C54: 250 | D54: Y | E54: =SUM(B54*0.5*3/27)*C54/13 -> 0 | F54: 0.35 | G54: Y | H54: =B54*F54 -> 0 | I54: =((((H54*$H$62)+(E54*(1+$C$62)))*(1+$B$67))*(1+$B$72)) -> 0 | J54: =IF(I54=0,0,I54/B54) -> 0
A55: Concrete | B55: 0 | C55: 90 | D55: Y | E55: =(B55*0.5*0.5/27)*C55 -> 0 | F55: 0.25 | G55: Y | H55: =B55*F55 -> 0 | I55: =((((H55*$H$62)+(E55*(1+$C$62)))*(1+$B$67))*(1+$B$72)) -> 0 | J55: =IF(I55=0,0,I55/B55) -> 0
A56: Quazite box | B56: 0 | C56: 500 | D56: E | E56: =(B56/27)*C56 -> 0 | F56: 4 | G56: E | H56: =B56*F56 -> 0 | I56: =((((H56*$H$62)+(E56*(1+$C$62)))*(1+$B$67))*(1+$B$72)) -> 0 | J56: =IF(I56=0,0,I56/B56) -> 0
A57: Bucket truck | B57: 0 | C57: 38 | D57: HR | E57: =B57*C57 -> 0 | F57: 0 | G57: HR | H57: =B57*F57 -> 0 | I57: =((((H57*$H$62)+(E57*(1+$C$62)))*(1+$B$67))*(1+$B$72)) -> 0 | J57: =IF(I57=0,0,I57/B57) -> 0
A58: Bucket truck w/operator | B58: 0 | C58: 38 | D58: HR | E58: =B58*C58 -> 0 | F58: 1 | G58: HR | H58: =B58*F58 -> 0 | I58: =((((H58*$H$62)+(E58*(1+$C$62)))*(1+$B$67))*(1+$B$72)) -> 0 | J58: =IF(I58=0,0,I58/B58) -> 0
A59: Boring, underground drilling | C59: 2.79 | D59: FT | E59: =B59*C59 -> 0 | F59: 0.25 | G59: FT | H59: =B59*F59 -> 0 | I59: =((((H59*$H$62)+(E59*(1+$C$62)))*(1+$B$67))*(1+$B$72)) -> 0 | J59: =IF(I59=0,0,I59/B59) -> 0
A60: Equipment maintenance | B60: 0 | C60: 1000 | D60: LOT | E60: =B60*C60 -> 0 | F60: 18 | G60: LOT | H60: =B60*F60 -> 0 | I60: =((((H60*$H$62)+(E60*(1+$C$62)))*(1+$B$67))*(1+$B$72)) -> 0 | J60: =IF(I60=0,0,I60/B60) -> 0
A61: SUBTOTAL | E61: =SUM(E6:E60) -> 0 | H61: =SUM(H6:H60) -> 0
C62: 0.1025 | D62: Tax | E62: =SUM(E61)*C62 -> 0 | F62: Hourly | G62: Cost | H62: 79
E63: =SUM(E61:E62) -> 0 | H63: =H61*H62 -> 0 | I63: =SUM(I4:I62) -> 0
A64: TOTAL MATERIAL | C64: =E63 -> 0 | D64: This streetlighting estimator is set up for commercial work. There may be need to alter the price for residential work. Labor cost is entered in cell H60 and automatically altered on the Job Set-Up sheet. All amounts in the yellow box are automatically transferred there also. The total estimated price needs to be manually entered on the Quote sheet.
...

Sheet PROPOSAL
E4: 817 S Kildare Ave
E5: Chicago, Illinois 60624
E6: Phone: 773.826.2600 Fax: 773.826.2620
E8: =basebid!F2 -> Todays Date
A10: =basebid!A5 -> Contact Name | E10: RE: | F10: =basebid!A2 -> Elevator/Lobby/Corridors & Vacant Suite 3450
A11: =basebid!A4 -> G.C. | F11: =basebid!A3 -> 120 N LaSalle
A12: =basebid!A6 -> Telephone - Fax | E12: Est# | F12: =basebid!D2 -> KM05
A14: We have prepared an electrical estimate regarding the above project.
A15: Our proposal is based on information and drawings provided.
A17: We have included the following items in our proposal.
A19: =-basebid!C11 -> 0 | B19: =basebid!A11 -> TEMP POWER | D19: =-basebid!C159 -> 0 | E19: =basebid!A159 -> MECHANICAL CONNECTIONS
A20: =-basebid!C12 -> 0 | B20: =basebid!A12 -> Temp power from ComEd permanent power | D20: =-basebid!C160 -> 0 | E20: =basebid!A160 -> Make Up Air Units - gas (warehouse)
A21: =-basebid!C13 -> 0 | B21: =basebid!A13 -> Hook up of construction trailer | D21: =-basebid!C161 -> 0 | E21: =basebid!A161 -> Roof Top Unit - gas (office)
A22: =-basebid!C14 -> 0 | B22: =basebid!A14 -> 0 | D22: =-basebid!C162 -> 0 | E22: =basebid!A162 -> Electric water heaters
A23: =-basebid!C15 -> 0 | B23: =basebid!A15 -> ELECTRICAL SERVICE & DISTRIBUTION | D23: =-basebid!C163 -> 0 | E23: =basebid!A163 -> 200 Amp Fire pump w/ 30' feed and meter
A24: =-basebid!C16 -> 0 | B24: =basebid!A16 -> ComEd pad | D24: =-basebid!C164 -> 0 | E24: =basebid!A164 -> Jockey pump
A25: =-basebid!C17 -> 0 | B25: =basebid!A17 -> Rework existing panel for new loads | D25: =-basebid!C165 -> 0 | E25: =basebid!A165 -> Hydraulic elevator
A26: =-basebid!C18 -> 0 | B26: =basebid!A18 -> 4000A., 277/480V., 3PH. Main switchboard w/ meter | D26: =-basebid!C166 -> 0 | E26: =basebid!A166 -> Exhaust Fan with Interlock Conduit
A27: =-basebid!C19 -> 0 | B27: =basebid!A19 -> 0 | D27: =-basebid!C167 -> 0 | E27: =basebid!A167 -> Unit Heater (gas)
A28: =-basebid!#REF! -> #REF! | B28: =basebid!#REF! -> #REF! | D28: =-basebid!C168 -> 0 | E28: =basebid!A168 -> Electric Wall heater (FBO)
A29: =-basebid!C21 -> 0 | B29: =basebid!A21 -> 3000A., 277/480V., 3PH. Main switchboard w/ meter | D29: =-basebid!C169 -> 0 | E29: =basebid!A169 -> Baseboard Heater (FBO)
A30: =-basebid!C22 -> 0 | B30: =basebid!A22 -> 0 | D30: =-basebid!C170 -> 0 | E30: =basebid!A170 -> Toilet Exhaust (FBO)
A31: =-basebid!#REF! -> #REF! | B31: =basebid!#REF! -> #REF! | D31: =-basebid!C171 -> 0 | E31: =basebid!A171 -> Sump Pump
A32: =-basebid!C24 -> 0 | B32: =basebid!A24 -> 2500A., 277/480V., 3PH. Main switchboard w/ meter | D32: =-basebid!C172 -> 0 | E32: =basebid!A172 -> 30A Equipment connection
A33: =-basebid!C25 -> 0 | B33: =basebid!A25 -> 0 | D33: =-basebid!C173 -> 0 | E33: =basebid!A173 -> 0
A34: =-basebid!#REF! -> #REF! | B34: =basebid!#REF! -> #REF! | D34: =-basebid!C174 -> 0 | E34: =basebid!A174 -> 40A Equipment connection
A35: =-basebid!C27 -> 0 | B35: =basebid!A27 -> 2000A., 277/480V., 3PH. Main switchboard w/ meter | D35: =-basebid!C175 -> 0 | E35: =basebid!A175 -> 0
A36: =-basebid!C28 -> 0 | B36: =basebid!A28 -> 0 | D36: =-basebid!C176 -> 0 | E36: =basebid!A176 -> 60A Equipment connection
A37: =-basebid!#REF! -> #REF! | B37: =basebid!#REF! -> #REF! | D37: =-basebid!C177 -> 0 | E37: =basebid!A177 -> 0
A38: =-basebid!C30 -> 0 | B38: =basebid!A30 -> 1600A., 277/480V., 3PH. Main switchboard w/ meter | D38: =-basebid!C178 -> 0 | E38: =basebid!A178 -> 100A Equipment connection
A39: =-basebid!C31 -> 0 | B39: =basebid!A31 -> 0 | D39: =-basebid!C179 -> 0 | E39: =basebid!A179 -> 0
A40: =-basebid!#REF! -> #REF! | B40: =basebid!#REF! -> #REF! | D40: =-basebid!C180 -> 0 | E40: =basebid!A180 -> 200A Equipment connection
A41: =-basebid!C33 -> 0 | B41: =basebid!A33 -> 1200A., 277/480V., 3PH. Main distribution board w/ ct/meter | D41: =-basebid!C181 -> 0 | E41: =basebid!A181 -> 0
A42: =-basebid!C34 -> 0 | B42: =basebid!A34 -> 0 | D42: =-basebid!C182 -> 0 | E42: =basebid!A182 -> 400A Equipment connection
A43: =-basebid!#REF! -> #REF! | B43: =basebid!#REF! -> #REF! | D43: =-basebid!C183 -> 0 | E43: =basebid!A183 -> 0
A44: =-basebid!C36 -> 0 | B44: =basebid!A36 -> 1000A., 277/480V., 3PH. Main distribution board w/ ct/meter | D44: =-basebid!C184 -> 0 | E44: =basebid!A184 -> 600A.Equipment connection
A45: =-basebid!C37 -> 0 | B45: =basebid!A37 -> 0 | D45: =-basebid!C185 -> 0 | E45: =basebid!A185 -> 0
A46: =-basebid!#REF! -> #REF! | B46: =basebid!#REF! -> #REF! | D46: =-basebid!C186 -> 0 | E46: =basebid!A186 -> 800A.Equipment connection
A47: =-basebid!C39 -> 0 | B47: =basebid!A39 -> 800A., 277/480V., 3PH. Distribution board w/ feed | D47: =-basebid!C187 -> 0 | E47: =basebid!A187 -> 0
A48: =-basebid!C40 -> 0 | B48: =basebid!A40 -> 0 | D48: =-basebid!C188 -> 0 | E48: =basebid!A188 -> 1200A.Equipment connection
...
